<mujoco model="mobile_ai">
  <compiler angle="radian" meshdir="../meshes" texturedir="../" autolimits="true"/>

  <option integrator="implicitfast" noslip_iterations="1"/>

  <default>
    <default class="visual">
      <geom type="mesh" group="2" contype="0" conaffinity="0" material="trossen_black"/>
    </default>
    <default class="collision">
      <geom type="cylinder" group="3" mass="0" density="0"/>
    </default>
  </default>

  <asset>
    <material name="trossen_black" rgba="0.1 0.1 0.1 1"/>
    <material name="trossen_gray" rgba="0.5 0.5 0.5 1"/>
    <material name="trossen_wheel" rgba="0.792157 0.819608 0.933333 1"/>

    <mesh name="mobile_base_link" file="mobile_base_link.stl" scale="0.001 0.001 0.001"/>
    <mesh name="wheel" file="wheel.stl"/>
    <mesh name="caster_swivel" file="caster_swivel.stl"/>
    <mesh name="caster_wheel" file="caster_wheel.stl"/>
    <mesh name="base_link" file="base_link.stl"/>
    <mesh name="link_1" file="link_1.stl"/>
    <mesh name="link_2" file="link_2.stl"/>
    <mesh name="link_3" file="link_3.stl"/>
    <mesh name="link_4" file="link_4.stl"/>
    <mesh name="link_5" file="link_5.stl"/>
    <mesh name="link_6" file="link_6.stl"/>
    <mesh name="carriage_right" file="carriage_right.stl"/>
    <mesh name="carriage_left" file="carriage_left.stl"/>
    <mesh name="camera_mount_d405" file="camera_mount_d405.stl"/>
    <mesh name="d405" file="d405.stl" scale="0.001 0.001 0.001"/>
    <mesh name="gripper_left" file="gripper_left.stl"/>
    <mesh name="gripper_right" file="gripper_right.stl"/>
  </asset>

  <worldbody>
    <body name="mobile_base_link" pos="0 0 0">
      <inertial pos="0.01556204 0.00159774 0.22495608" quat="0.707127741 -0.001023103 -0.707084574 -0.000846845" mass="80" diaginertia="0.560183611 0.631096120 0.800609086"/>
      <freejoint name="mobile_base_freejoint"/>
      <geom class="visual" material="trossen_gray" pos="0 0 0.211" quat="0.707107 -0.707107 0 0" mesh="mobile_base_link"/>
      <geom class="collision" type="box" size="0.19 0.27 0.3" pos="0 0 0.511"/>
      <geom class="collision" type="box" size="0.28 0.28 0.09" pos="0 0 0.121"/>
      <geom class="collision" type="box" size="0.035 0.04 0.115" pos="0.155 -0.23 0.926"/>
      <geom class="collision" type="box" size="0.035 0.04 0.115" pos="0.155 0.23 0.926"/>
      <geom class="collision" type="box" size="0.025 0.27 0.02" pos="0.215 0 1.022"/>
      <geom class="collision" type="box" size="0.065 0.1225 0.02" pos="0.3017 -0.265 1.022"/>
      <geom class="collision" type="box" size="0.065 0.1225 0.02" pos="0.3017 0.265 1.022"/>
      <geom class="collision" type="box" size="0.0025 0.0275 0.1125" pos="0.1875 0 1.151"/>

      <geom class="visual" type="box" size="0.0115 0.021 0.021" pos="0.224879 0 1.25771" quat="0.948324 0 0.317305 0"/>
      <geom class="collision" type="box" size="0.0365 0.025 0.025" pos="0.204879 0 1.27271" quat="0.948324 0 0.317305 0"/>
      <site name="cam_high_color_frame" pos="0.231879 0.009 1.25071" quat="0.948324 0 0.317305 0" size="0.005"/>
      <camera name="cam_high" pos="0.231879 0.009 1.25071" quat="0.6329 0.3155 -0.3155 -0.6329" mode="fixed" fovy="120"/>

      <body name="left_wheel_link" pos="0 0.192 0.0851">
        <inertial pos="0 0 0" quat="0.707107 0 0 0.707107" mass="3" diaginertia="0.00291162 0.00165793 0.00165793"/>
        <joint name="left_wheel" pos="0 0 0" axis="0 1 0" actuatorfrcrange="-4 4" frictionloss="0.1" armature="0.005"/>
        <geom class="visual" material="trossen_wheel" mesh="wheel"/>
        <geom name="left_wheel_collision" class="collision" type="sphere" size="0.085"/>
      </body>
      <body name="right_wheel_link" pos="0 -0.192 0.0851">
        <inertial pos="0 0 0" quat="0.707107 0 0 0.707107" mass="3" diaginertia="0.00291162 0.00165793 0.00165793"/>
        <joint name="right_wheel" pos="0 0 0" axis="0 1 0" actuatorfrcrange="-4 4" frictionloss="0.1" armature="0.005"/>
        <geom class="visual" material="trossen_wheel" mesh="wheel"/>
        <geom name="right_wheel_collision" class="collision" type="sphere" size="0.085"/>
      </body>
      <body name="caster_swivel_front_left" pos="0.168 0.17 0.104">
        <inertial pos="-0.00642926 0 -0.0232438" quat="0.959318 0 -0.282329 0" mass="0.1" diaginertia="3.80031e-05 3.55224e-05 2.07153e-05"/>
        <joint name="caster_swivel_joint_front_left" pos="0 0 0" axis="0 0 1"/>
        <geom class="visual" material="trossen_wheel" mesh="caster_swivel"/>
        <body name="caster_wheel_front_left" pos="-0.0345 0 -0.066">
          <inertial pos="0 0 0" quat="0.707107 0 0 0.707107" mass="0.535" diaginertia="6.42431e-05 3.50668e-05 3.50668e-05"/>
          <joint name="caster_wheel_joint_front_left" pos="0 0 0" axis="0 1 0"/>
          <geom class="visual" material="trossen_wheel" mesh="caster_wheel"/>
          <geom class="collision" type="sphere" size="0.038"/>
        </body>
      </body>
      <body name="caster_swivel_front_right" pos="0.16843 -0.17 0.104">
        <inertial pos="-0.00642926 0 -0.0232438" quat="0.959318 0 -0.282329 0" mass="0.1" diaginertia="3.80031e-05 3.55224e-05 2.07153e-05"/>
        <joint name="caster_swivel_joint_front_right" pos="0 0 0" axis="0 0 1"/>
        <geom class="visual" material="trossen_wheel" mesh="caster_swivel"/>
        <body name="caster_wheel_front_right" pos="-0.0345 0 -0.066">
          <inertial pos="0 0 0" quat="0.707107 0 0 0.707107" mass="0.535" diaginertia="6.42431e-05 3.50668e-05 3.50668e-05"/>
          <joint name="caster_wheel_joint_front_right" pos="0 0 0" axis="0 1 0"/>
          <geom class="visual" material="trossen_wheel" mesh="caster_wheel"/>
          <geom class="collision" type="sphere" size="0.038"/>
        </body>
      </body>
      <body name="caster_swivel_rear_left" pos="-0.16783 0.17 0.104">
        <inertial pos="-0.00642926 0 -0.0232438" quat="0.959318 0 -0.282329 0" mass="0.1" diaginertia="3.80031e-05 3.55224e-05 2.07153e-05"/>
        <joint name="caster_swivel_joint_rear_left" pos="0 0 0" axis="0 0 1"/>
        <geom class="visual" material="trossen_wheel" mesh="caster_swivel"/>
        <body name="caster_wheel_rear_left" pos="-0.0345 0 -0.066">
          <inertial pos="0 0 0" quat="0.707107 0 0 0.707107" mass="0.535" diaginertia="6.42431e-05 3.50668e-05 3.50668e-05"/>
          <joint name="caster_wheel_joint_rear_left" pos="0 0 0" axis="0 1 0"/>
          <geom class="visual" material="trossen_wheel" mesh="caster_wheel"/>
          <geom class="collision" type="sphere" size="0.038"/>
        </body>
      </body>
      <body name="caster_swivel_rear_right" pos="-0.168 -0.17 0.104">
        <inertial pos="-0.00642926 0 -0.0232438" quat="0.959318 0 -0.282329 0" mass="0.1" diaginertia="3.80031e-05 3.55224e-05 2.07153e-05"/>
        <joint name="caster_swivel_joint_rear_right" pos="0 0 0" axis="0 0 1"/>
        <geom class="visual" material="trossen_wheel" mesh="caster_swivel"/>
        <body name="caster_wheel_rear_right" pos="-0.0345 0 -0.066">
          <inertial pos="0 0 0" quat="0.707107 0 0 0.707107" mass="0.535" diaginertia="6.42431e-05 3.50668e-05 3.50668e-05"/>
          <joint name="caster_wheel_joint_rear_right" pos="0 0 0" axis="0 1 0"/>
          <geom class="visual" material="trossen_wheel" mesh="caster_wheel"/>
          <geom class="collision" type="sphere" size="0.038"/>
        </body>
      </body>
      <body name="follower_left/base_link" pos="0.331 0.3 1.042">
        <inertial pos="-0.00014175 -5.228e-05 0.03175177" quat="0.503748 -0.507380 -0.494230 -0.494510" mass="0.45969858" diaginertia="0.000213926 0.000416701 0.000448963"/>
        <geom class="visual" mesh="base_link"/>
        <geom class="collision" type="cylinder" size="0.031 0.0325" pos="0 0 0.0325" quat="1 0 0 0"/>
        <body name="follower_left/link_1" pos="0 0 0.05725">
          <inertial pos="-0.00011075 0.00171176 0.0204459" quat="0.313955 0.305238 -0.643575 0.627752" mass="0.152704" diaginertia="0.000203432 0.000173907 8.3521e-05"/>
          <joint name="follower_left/joint_0" pos="0 0 0" axis="0 0 1" range="-3.05433 3.05433" armature="0.032" frictionloss="0.1"/>
          <geom class="visual" mesh="link_1"/>
          <body name="follower_left/link_2" pos="0.02 0 0.04625">
            <inertial pos="-0.131215 -0.00292583 0.00021345" quat="-0.00123582 0.706546 -0.00109575 0.707665" mass="1.15316" diaginertia="0.0179449 0.0173612 0.00102628"/>
            <joint name="follower_left/joint_1" pos="0 0 0" axis="0 1 0" range="0 3.14159" armature="0.032" frictionloss="0.1"/>
            <geom class="visual" mesh="link_2"/>
            <geom class="collision" type="capsule" size="0.031 0.015" pos="0 0 0" quat="1 1 0 0"/>
            <geom class="collision" type="box" size="0.0975 0.02 0.02" pos="-0.131 0 0" quat="1 0 0 0"/>
            <body name="follower_left/link_3" pos="-0.264 0 0">
              <inertial pos="0.180836 -0.0009409 0.0555494" quat="0.0103901 0.669684 -0.0033175 0.742566" mass="0.686666" diaginertia="0.00566898 0.00547578 0.00059316"/>
              <joint name="follower_left/joint_2" pos="0 0 0" axis="0 -1 0" range="0 2.35619" armature="0.032" frictionloss="0.1"/>
              <geom class="visual" mesh="link_3"/>
              <geom class="collision" type="capsule" size="0.031 0.015" pos="0 0 0" quat="1 1 0 0"/>
              <geom class="collision" type="box" size="0.08 0.02 0.02" pos="0.13 0 0.06" quat="1 0 0 0"/>
              <body name="follower_left/link_4" pos="0.245 0 0.06">
                <inertial pos="0.0579784 0.00027145 0.0588445" quat="0.948688 0.0346237 0.307828 0.0635164" mass="0.457899" diaginertia="0.000670827 0.000661455 0.000288648"/>
                <joint name="follower_left/joint_3" pos="0 0 0" axis="0 -1 0" range="-1.5708 1.5708" armature="0.0018" frictionloss="0.1"/>
                <geom class="visual" mesh="link_4"/>
                <geom class="collision" type="capsule" size="0.031 0.015" pos="0 0 0" quat="1 1 0 0"/>
                <body name="follower_left/link_5" pos="0.06775 0 0.0455">
                  <inertial pos="0.00412447 -1.138e-05 -0.0428318" quat="0.496144 0.502128 0.503595 0.498098" mass="0.366939" diaginertia="0.000320622 0.00026751 0.000189108"/>
                  <joint name="follower_left/joint_4" pos="0 0 0" axis="0 0 -1" range="-1.5708 1.5708" armature="0.0018" frictionloss="0.1"/>
                  <geom class="visual" mesh="link_5"/>
                  <geom class="collision" type="cylinder" size="0.031 0.028" pos="0 0 0.03" quat="1 0 0 0"/>
                  <body name="follower_left/link_6" pos="0.02895 0 -0.0455">
                    <inertial pos="0.046841 0.00145133 0.00895674" quat="0.275854 0.291255 -0.691957 0.600225" mass="0.671874" diaginertia="0.00118316 0.00110863 0.00078309"/>
                    <joint name="follower_left/joint_5" pos="0 0 0" axis="1 0 0" range="-3.14159 3.14159" armature="0.0018" frictionloss="0.1"/>
                    <geom class="visual" mesh="link_6"/>
                    <geom class="collision" type="cylinder" size="0.029 0.05" pos="0 0 0" quat="1 0 1 0"/>
                    <geom class="collision" type="box" size="0.0125 0.094 0.031" pos="0.0685 0 0" quat="1 0 0 0"/>
                    <geom class="visual" pos="0.012 0 0" quat="1 0 0 0" mesh="camera_mount_d405"/>
                    <geom class="collision" type="box" size="0.0155 0.025 0.025" pos="0.0513206 0 0.0569399" quat="0.984808 0 0.173648 0"/>
                    <geom class="visual" type="box" size="0.0115 0.021 0.021" pos="0.0513206 0 0.0569399" quat="0.984808 0 0.173648 0"/>
                    <site name="follower_left/camera_color_frame" pos="0.05864 0.009 0.05427" quat="0.9848078 0 0.1736482 0" size="0.005"/>
                    <camera name="cam_left_wrist" pos="0.05864 0.009 0.05427" quat="0.5793 0.4056 -0.4056 -0.5793" mode="fixed" fovy="87"/>
                    <body name="follower_left/carriage_right" pos="0.0865 -0.023 0">
                      <inertial pos="0.00169015 0.00592793 0.00201817" quat="-0.370973 0.740886 -0.0847721 0.553427" mass="0.081271" diaginertia="4.29565e-05 3.87081e-05 2.21528e-05"/>
                      <joint name="follower_left/right_carriage_joint" pos="0 0 0" axis="0 -1 0" type="slide" range="0 0.044" armature="0.1" frictionloss="0.1"/>
                      <geom class="visual" mesh="carriage_right"/>
                      <geom class="visual" mesh="gripper_right"/>
                      <geom name="follower_left/gripper_right_pad_upper" class="collision" type="box" size="0.0275 0.005 0.01" pos="0.0286 0.01436 0.0037" quat="0.99257 -0.00451 0.10246 0.06547"/>
                      <geom name="follower_left/gripper_right_pad_lower" class="collision" type="box" size="0.0275 0.005 0.01" pos="0.0285 0.01429 -0.00973" quat="0.98344 0.0133 -0.16893 0.06427"/>
                      <geom name="follower_left/gripper_right_tip" class="collision" type="box" size="0.00732 0.00214 0.00767" pos="0.0622 0.02083 -0.00105" quat="1 0 0 0"/>
                    </body>
                    <body name="follower_left/carriage_left" pos="0.0865 0.023 0">
                      <inertial pos="0.00169017 -0.00592796 -0.00365701" quat="-0.0382691 0.628022 -0.255101 0.734198" mass="0.081271" diaginertia="4.21112e-05 3.61943e-05 2.40003e-05"/>
                      <joint name="follower_left/left_carriage_joint" pos="0 0 0" axis="0 1 0" type="slide" range="0 0.044" armature="0.1" frictionloss="0.1"/>
                      <geom class="visual" mesh="carriage_left"/>
                      <geom class="visual" mesh="gripper_left"/>
                      <geom name="follower_left/gripper_left_pad_upper" class="collision" type="box" size="0.0275 0.005 0.01" pos="0.0286 -0.01436 0.0037" quat="0.99257 0.00451 0.10246 -0.06547"/>
                      <geom name="follower_left/gripper_left_pad_lower" class="collision" type="box" size="0.0275 0.005 0.01" pos="0.0285 -0.01429 -0.00973" quat="0.98344 -0.0133 -0.16893 -0.06427"/>
                      <geom name="follower_left/gripper_left_tip" class="collision" type="box" size="0.00732 0.00214 0.00767" pos="0.0622 -0.02083 -0.00105" quat="1 0 0 0"/>
                    </body>
                  </body>
                </body>
              </body>
            </body>
          </body>
        </body>
      </body>
      <body name="follower_right/base_link" pos="0.331 -0.3 1.042">
        <inertial pos="-0.00014175 -5.228e-05 0.03175177" quat="0.503748 -0.507380 -0.494230 -0.494510" mass="0.45969858" diaginertia="0.000213926 0.000416701 0.000448963"/>
        <geom class="visual" mesh="base_link"/>
        <geom class="collision" type="cylinder" size="0.031 0.0325" pos="0 0 0.0325" quat="1 0 0 0"/>
        <body name="follower_right/link_1" pos="0 0 0.05725">
          <inertial pos="-0.00011075 0.00171176 0.0204459" quat="0.313955 0.305238 -0.643575 0.627752" mass="0.152704" diaginertia="0.000203432 0.000173907 8.3521e-05"/>
          <joint name="follower_right/joint_0" pos="0 0 0" axis="0 0 1" range="-3.05433 3.05433" armature="0.032" frictionloss="0.1"/>
          <geom class="visual" mesh="link_1"/>
          <body name="follower_right/link_2" pos="0.02 0 0.04625">
            <inertial pos="-0.131215 -0.00292583 0.00021345" quat="-0.00123582 0.706546 -0.00109575 0.707665" mass="1.15316" diaginertia="0.0179449 0.0173612 0.00102628"/>
            <joint name="follower_right/joint_1" pos="0 0 0" axis="0 1 0" range="0 3.14159" armature="0.032" frictionloss="0.1"/>
            <geom class="visual" mesh="link_2"/>
            <geom class="collision" type="capsule" size="0.031 0.015" pos="0 0 0" quat="1 1 0 0"/>
            <geom class="collision" type="box" size="0.0975 0.02 0.02" pos="-0.131 0 0" quat="1 0 0 0"/>
            <body name="follower_right/link_3" pos="-0.264 0 0">
              <inertial pos="0.180836 -0.0009409 0.0555494" quat="0.0103901 0.669684 -0.0033175 0.742566" mass="0.686666" diaginertia="0.00566898 0.00547578 0.00059316"/>
              <joint name="follower_right/joint_2" pos="0 0 0" axis="0 -1 0" range="0 2.35619" armature="0.032" frictionloss="0.1"/>
              <geom class="visual" mesh="link_3"/>
              <geom class="collision" type="capsule" size="0.031 0.015" pos="0 0 0" quat="1 1 0 0"/>
              <geom class="collision" type="box" size="0.08 0.02 0.02" pos="0.13 0 0.06" quat="1 0 0 0"/>
              <body name="follower_right/link_4" pos="0.245 0 0.06">
                <inertial pos="0.0579784 0.00027145 0.0588445" quat="0.948688 0.0346237 0.307828 0.0635164" mass="0.457899" diaginertia="0.000670827 0.000661455 0.000288648"/>
                <joint name="follower_right/joint_3" pos="0 0 0" axis="0 -1 0" range="-1.5708 1.5708" armature="0.0018" frictionloss="0.1"/>
                <geom class="visual" mesh="link_4"/>
                <geom class="collision" type="capsule" size="0.031 0.015" pos="0 0 0" quat="1 1 0 0"/>
                <body name="follower_right/link_5" pos="0.06775 0 0.0455">
                  <inertial pos="0.00412447 -1.138e-05 -0.0428318" quat="0.496144 0.502128 0.503595 0.498098" mass="0.366939" diaginertia="0.000320622 0.00026751 0.000189108"/>
                  <joint name="follower_right/joint_4" pos="0 0 0" axis="0 0 -1" range="-1.5708 1.5708" armature="0.0018" frictionloss="0.1"/>
                  <geom class="visual" mesh="link_5"/>
                  <geom class="collision" type="cylinder" size="0.031 0.028" pos="0 0 0.03" quat="1 0 0 0"/>
                  <body name="follower_right/link_6" pos="0.02895 0 -0.0455">
                    <inertial pos="0.046841 0.00145133 0.00895674" quat="0.275854 0.291255 -0.691957 0.600225" mass="0.671874" diaginertia="0.00118316 0.00110863 0.00078309"/>
                    <joint name="follower_right/joint_5" pos="0 0 0" axis="1 0 0" range="-3.14159 3.14159" armature="0.0018" frictionloss="0.1"/>
                    <geom class="visual" mesh="link_6"/>
                    <geom class="collision" type="cylinder" size="0.029 0.05" pos="0 0 0" quat="1 0 1 0"/>
                    <geom class="collision" type="box" size="0.0125 0.094 0.031" pos="0.0685 0 0" quat="1 0 0 0"/>
                    <geom class="visual" pos="0.012 0 0" quat="1 0 0 0" mesh="camera_mount_d405"/>
                    <geom class="collision" type="box" size="0.0155 0.025 0.025" pos="0.0513206 0 0.0569399" quat="0.984808 0 0.173648 0"/>
                    <geom class="visual" type="box" size="0.0115 0.021 0.021" pos="0.0513206 0 0.0569399" quat="0.984808 0 0.173648 0"/>
                    <site name="follower_right/camera_color_frame" pos="0.05864 0.009 0.05427" quat="0.9848078 0 0.1736482 0" size="0.005"/>
                    <camera name="cam_right_wrist" pos="0.05864 0.009 0.05427" quat="0.5793 0.4056 -0.4056 -0.5793" mode="fixed" fovy="87"/>
                    <body name="follower_right/carriage_right" pos="0.0865 -0.023 0">
                      <inertial pos="0.00169015 0.00592793 0.00201817" quat="-0.370973 0.740886 -0.0847721 0.553427" mass="0.081271" diaginertia="4.29565e-05 3.87081e-05 2.21528e-05"/>
                      <joint name="follower_right/right_carriage_joint" pos="0 0 0" axis="0 -1 0" type="slide" range="0 0.044" armature="0.1" frictionloss="0.1"/>
                      <geom class="visual" mesh="carriage_right"/>
                      <geom class="visual" mesh="gripper_right"/>
                      <geom name="follower_right/gripper_right_pad_upper" class="collision" type="box" size="0.0275 0.005 0.01" pos="0.0286 0.01436 0.0037" quat="0.99257 -0.00451 0.10246 0.06547"/>
                      <geom name="follower_right/gripper_right_pad_lower" class="collision" type="box" size="0.0275 0.005 0.01" pos="0.0285 0.01429 -0.00973" quat="0.98344 0.0133 -0.16893 0.06427"/>
                      <geom name="follower_right/gripper_right_tip" class="collision" type="box" size="0.00732 0.00214 0.00767" pos="0.0622 0.02083 -0.00105" quat="1 0 0 0"/>
                    </body>
                    <body name="follower_right/carriage_left" pos="0.0865 0.023 0">
                      <inertial pos="0.00169017 -0.00592796 -0.00365701" quat="-0.0382691 0.628022 -0.255101 0.734198" mass="0.081271" diaginertia="4.21112e-05 3.61943e-05 2.40003e-05"/>
                      <joint name="follower_right/left_carriage_joint" pos="0 0 0" axis="0 1 0" type="slide" range="0 0.044" armature="0.1" frictionloss="0.1"/>
                      <geom class="visual" mesh="carriage_left"/>
                      <geom class="visual" mesh="gripper_left"/>
                      <geom name="follower_right/gripper_left_pad_upper" class="collision" type="box" size="0.0275 0.005 0.01" pos="0.0286 -0.01436 0.0037" quat="0.99257 0.00451 0.10246 -0.06547"/>
                      <geom name="follower_right/gripper_left_pad_lower" class="collision" type="box" size="0.0275 0.005 0.01" pos="0.0285 -0.01429 -0.00973" quat="0.98344 -0.0133 -0.16893 -0.06427"/>
                      <geom name="follower_right/gripper_left_tip" class="collision" type="box" size="0.00732 0.00214 0.00767" pos="0.0622 -0.02083 -0.00105" quat="1 0 0 0"/>
                    </body>
                  </body>
                </body>
              </body>
            </body>
          </body>
        </body>
      </body>
    </body>
  </worldbody>

  <equality>
    <joint joint1="follower_left/right_carriage_joint" joint2="follower_left/left_carriage_joint" polycoef="0 1 0 0 0"/>
    <joint joint1="follower_right/right_carriage_joint" joint2="follower_right/left_carriage_joint" polycoef="0 1 0 0 0"/>
  </equality>

  <contact>
    <exclude body1="mobile_base_link" body2="left_wheel_link"/>
    <exclude body1="mobile_base_link" body2="right_wheel_link"/>
    <exclude body1="mobile_base_link" body2="caster_swivel_front_left"/>
    <exclude body1="mobile_base_link" body2="caster_swivel_front_right"/>
    <exclude body1="mobile_base_link" body2="caster_swivel_rear_left"/>
    <exclude body1="mobile_base_link" body2="caster_swivel_rear_right"/>
    <exclude body1="mobile_base_link" body2="caster_wheel_front_left"/>
    <exclude body1="mobile_base_link" body2="caster_wheel_front_right"/>
    <exclude body1="mobile_base_link" body2="caster_wheel_rear_left"/>
    <exclude body1="mobile_base_link" body2="caster_wheel_rear_right"/>
  </contact>

  <actuator>
    <velocity name="left_wheel" joint="left_wheel" kv="1000" ctrlrange="-12.566370614359172 12.566370614359172" forcerange="-4 4"/>
    <velocity name="right_wheel" joint="right_wheel" kv="1000" ctrlrange="-12.566370614359172 12.566370614359172" forcerange="-4 4"/>

    <position name="follower_left/joint_0" joint="follower_left/joint_0" kp="40" kv="2.5" ctrlrange="-3.05433 3.05433" forcerange="-27 27"/>
    <position name="follower_left/joint_1" joint="follower_left/joint_1" kp="40" kv="2.5" ctrlrange="0 3.14159" forcerange="-27 27"/>
    <position name="follower_left/joint_2" joint="follower_left/joint_2" kp="40" kv="2.5" ctrlrange="0 2.35619" forcerange="-27 27"/>
    <position name="follower_left/joint_3" joint="follower_left/joint_3" kp="20" kv="0.5" ctrlrange="-1.5708 1.5708" forcerange="-7 7"/>
    <position name="follower_left/joint_4" joint="follower_left/joint_4" kp="10" kv="1" ctrlrange="-1.5708 1.5708" forcerange="-7 7"/>
    <position name="follower_left/joint_5" joint="follower_left/joint_5" kp="10" kv="1" ctrlrange="-3.14159 3.14159" forcerange="-7 7"/>
    <position name="follower_left/gripper" joint="follower_left/left_carriage_joint" kp="100" kv="10" ctrlrange="0 0.044" forcerange="-400 400"/>

    <position name="follower_right/joint_0" joint="follower_right/joint_0" kp="40" kv="2.5" ctrlrange="-3.05433 3.05433" forcerange="-27 27"/>
    <position name="follower_right/joint_1" joint="follower_right/joint_1" kp="40" kv="2.5" ctrlrange="0 3.14159" forcerange="-27 27"/>
    <position name="follower_right/joint_2" joint="follower_right/joint_2" kp="40" kv="2.5" ctrlrange="0 2.35619" forcerange="-27 27"/>
    <position name="follower_right/joint_3" joint="follower_right/joint_3" kp="20" kv="0.5" ctrlrange="-1.5708 1.5708" forcerange="-7 7"/>
    <position name="follower_right/joint_4" joint="follower_right/joint_4" kp="10" kv="1" ctrlrange="-1.5708 1.5708" forcerange="-7 7"/>
    <position name="follower_right/joint_5" joint="follower_right/joint_5" kp="10" kv="1" ctrlrange="-3.14159 3.14159" forcerange="-7 7"/>
    <position name="follower_right/gripper" joint="follower_right/left_carriage_joint" kp="100" kv="10" ctrlrange="0 0.044" forcerange="-400 400"/>
  </actuator>

  <keyframe>
    <key name="home" qpos="0 0 0 0 0 0 0 0 0 0 0 0 0 0 0 0 0 0 0 0 0 0 0 0 0 0" ctrl="0 0 0 0 0 0 0 0 0 0 0 0 0 0 0 0"/>
  </keyframe>
</mujoco>
